

[34m[1mwandb[39m[22m: Downloading large artifact model-mheh9e55:latest, 1673.44MB. 7 files... Done. 0:0:0

[34m[1mwandb[39m[22m: Downloading large artifact model-mheh9e55:latest, 1673.44MB. 7 files... Done. 0:0:0
  0%|          | 0/1 [00:00<?, ?it/s]
Exception in thread ChkStopThr:
Traceback (most recent call last):
  File "/usr/local/Cellar/python@3.9/3.9.6/Frameworks/Python.framework/Versions/3.9/lib/python3.9/threading.py", line 973, in _bootstrap_inner
    self.run()
  File "/usr/local/Cellar/python@3.9/3.9.6/Frameworks/Python.framework/Versions/3.9/lib/python3.9/threading.py", line 910, in run
    self._target(*self._args, **self._kwargs)
  File "/usr/local/lib/python3.9/site-packages/wandb/sdk/wandb_run.py", line 170, in check_status
    status_response = self._interface.communicate_stop_status()
Exception in thread NetStatThr:
Traceback (most recent call last):
  File "/usr/local/Cellar/python@3.9/3.9.6/Frameworks/Python.framework/Versions/3.9/lib/python3.9/threading.py", line 973, in _bootstrap_inner
  File "/usr/local/lib/python3.9/site-packages/wandb/sdk/interface/interface.py", line 114, in communicate_stop_status
    self.run()
  File "/usr/local/Cellar/python@3.9/3.9.6/Frameworks/Python.framework/Versions/3.9/lib/python3.9/threading.py", line 910, in run
    self._target(*self._args, **self._kwargs)
    resp = self._communicate_stop_status(status)
  File "/usr/local/lib/python3.9/site-packages/wandb/sdk/wandb_run.py", line 152, in check_network_status
  File "/usr/local/lib/python3.9/site-packages/wandb/sdk/interface/interface_shared.py", line 395, in _communicate_stop_status
    status_response = self._interface.communicate_network_status()
  File "/usr/local/lib/python3.9/site-packages/wandb/sdk/interface/interface.py", line 125, in communicate_network_status
    resp = self._communicate(req, local=True)
  File "/usr/local/lib/python3.9/site-packages/wandb/sdk/interface/interface_shared.py", line 226, in _communicate
    resp = self._communicate_network_status(status)
  File "/usr/local/lib/python3.9/site-packages/wandb/sdk/interface/interface_shared.py", line 405, in _communicate_network_status
    resp = self._communicate(req, local=True)
  File "/usr/local/lib/python3.9/site-packages/wandb/sdk/interface/interface_shared.py", line 226, in _communicate
    return self._communicate_async(rec, local=local).get(timeout=timeout)
  File "/usr/local/lib/python3.9/site-packages/wandb/sdk/interface/interface_shared.py", line 231, in _communicate_async
    return self._communicate_async(rec, local=local).get(timeout=timeout)
  File "/usr/local/lib/python3.9/site-packages/wandb/sdk/interface/interface_shared.py", line 231, in _communicate_async
    raise Exception("The wandb backend process has shutdown")
Exception: The wandb backend process has shutdown
    raise Exception("The wandb backend process has shutdown")
