2022-04-26 10:13:07,052 INFO    MainThread:6466 [wandb_setup.py:_flush():75] Loading settings from /Users/max/.config/wandb/settings
2022-04-26 10:13:07,052 INFO    MainThread:6466 [wandb_setup.py:_flush():75] Loading settings from /Users/max/Developer/future-studio-lab/dalle-playground/backend/wandb/settings
2022-04-26 10:13:07,052 INFO    MainThread:6466 [wandb_setup.py:_flush():75] Loading settings from environment variables: {}
2022-04-26 10:13:07,052 INFO    MainThread:6466 [wandb_setup.py:_flush():75] Inferring run settings from compute environment: {'program_relpath': 'app.py', 'program': '/Users/max/Developer/future-studio-lab/dalle-playground/backend/app.py'}
2022-04-26 10:13:07,052 INFO    MainThread:6466 [wandb_setup.py:_flush():75] Applying login settings: {'anonymous': 'must'}
2022-04-26 10:13:07,053 INFO    MainThread:6466 [wandb_init.py:_log_setup():437] Logging user logs to /Users/max/Developer/future-studio-lab/dalle-playground/backend/wandb/run-20220426_101307-234c0qrn/logs/debug.log
2022-04-26 10:13:07,053 INFO    MainThread:6466 [wandb_init.py:_log_setup():438] Logging internal logs to /Users/max/Developer/future-studio-lab/dalle-playground/backend/wandb/run-20220426_101307-234c0qrn/logs/debug-internal.log
2022-04-26 10:13:07,053 INFO    MainThread:6466 [wandb_init.py:init():471] calling init triggers
2022-04-26 10:13:07,053 INFO    MainThread:6466 [wandb_init.py:init():474] wandb.init called with sweep_config: {}
config: {}
2022-04-26 10:13:07,053 INFO    MainThread:6466 [wandb_init.py:init():524] starting backend
2022-04-26 10:13:07,053 INFO    MainThread:6466 [backend.py:_multiprocessing_setup():97] multiprocessing start_methods=spawn,fork,forkserver, using: spawn
2022-04-26 10:13:07,075 INFO    MainThread:6466 [backend.py:ensure_launched():217] starting backend process...
2022-04-26 10:13:07,086 INFO    MainThread:6466 [backend.py:ensure_launched():222] started backend process with pid: 6474
2022-04-26 10:13:07,088 INFO    MainThread:6466 [wandb_init.py:init():533] backend started and connected
2022-04-26 10:13:07,099 INFO    MainThread:6466 [wandb_init.py:init():597] updated telemetry
2022-04-26 10:13:07,113 INFO    MainThread:6466 [wandb_init.py:init():628] communicating run to backend with 30 second timeout
2022-04-26 10:13:35,921 ERROR   Thread-2  :6466 [retry.py:__call__():126] Retry attempt failed:
Traceback (most recent call last):
  File "/Users/max/opt/anaconda3/lib/python3.9/site-packages/urllib3/connectionpool.py", line 445, in _make_request
    six.raise_from(e, None)
  File "<string>", line 3, in raise_from
  File "/Users/max/opt/anaconda3/lib/python3.9/site-packages/urllib3/connectionpool.py", line 440, in _make_request
    httplib_response = conn.getresponse()
  File "/Users/max/opt/anaconda3/lib/python3.9/http/client.py", line 1371, in getresponse
    response.begin()
  File "/Users/max/opt/anaconda3/lib/python3.9/http/client.py", line 319, in begin
    version, status, reason = self._read_status()
  File "/Users/max/opt/anaconda3/lib/python3.9/http/client.py", line 280, in _read_status
    line = str(self.fp.readline(_MAXLINE + 1), "iso-8859-1")
  File "/Users/max/opt/anaconda3/lib/python3.9/socket.py", line 704, in readinto
    return self._sock.recv_into(b)
  File "/Users/max/opt/anaconda3/lib/python3.9/ssl.py", line 1241, in recv_into
    return self.read(nbytes, buffer)
  File "/Users/max/opt/anaconda3/lib/python3.9/ssl.py", line 1099, in read
    return self._sslobj.read(len, buffer)
socket.timeout: The read operation timed out

During handling of the above exception, another exception occurred:

Traceback (most recent call last):
  File "/Users/max/opt/anaconda3/lib/python3.9/site-packages/requests/adapters.py", line 439, in send
    resp = conn.urlopen(
  File "/Users/max/opt/anaconda3/lib/python3.9/site-packages/urllib3/connectionpool.py", line 755, in urlopen
    retries = retries.increment(
  File "/Users/max/opt/anaconda3/lib/python3.9/site-packages/urllib3/util/retry.py", line 532, in increment
    raise six.reraise(type(error), error, _stacktrace)
  File "/Users/max/opt/anaconda3/lib/python3.9/site-packages/urllib3/packages/six.py", line 770, in reraise
    raise value
  File "/Users/max/opt/anaconda3/lib/python3.9/site-packages/urllib3/connectionpool.py", line 699, in urlopen
    httplib_response = self._make_request(
  File "/Users/max/opt/anaconda3/lib/python3.9/site-packages/urllib3/connectionpool.py", line 447, in _make_request
    self._raise_timeout(err=e, url=url, timeout_value=read_timeout)
  File "/Users/max/opt/anaconda3/lib/python3.9/site-packages/urllib3/connectionpool.py", line 336, in _raise_timeout
    raise ReadTimeoutError(
urllib3.exceptions.ReadTimeoutError: HTTPSConnectionPool(host='api.wandb.ai', port=443): Read timed out. (read timeout=10)

During handling of the above exception, another exception occurred:

Traceback (most recent call last):
  File "/Users/max/opt/anaconda3/lib/python3.9/site-packages/wandb/sdk/lib/retry.py", line 102, in __call__
    result = self._call_fn(*args, **kwargs)
  File "/Users/max/opt/anaconda3/lib/python3.9/site-packages/wandb/sdk/internal/internal_api.py", line 140, in execute
    return self.client.execute(*args, **kwargs)
  File "/Users/max/opt/anaconda3/lib/python3.9/site-packages/wandb/vendor/gql-0.2.0/wandb_gql/client.py", line 52, in execute
    result = self._get_result(document, *args, **kwargs)
  File "/Users/max/opt/anaconda3/lib/python3.9/site-packages/wandb/vendor/gql-0.2.0/wandb_gql/client.py", line 60, in _get_result
    return self.transport.execute(document, *args, **kwargs)
  File "/Users/max/opt/anaconda3/lib/python3.9/site-packages/wandb/vendor/gql-0.2.0/wandb_gql/transport/requests.py", line 38, in execute
    request = requests.post(self.url, **post_args)
  File "/Users/max/opt/anaconda3/lib/python3.9/site-packages/requests/api.py", line 117, in post
    return request('post', url, data=data, json=json, **kwargs)
  File "/Users/max/opt/anaconda3/lib/python3.9/site-packages/requests/api.py", line 61, in request
    return session.request(method=method, url=url, **kwargs)
  File "/Users/max/opt/anaconda3/lib/python3.9/site-packages/requests/sessions.py", line 542, in request
    resp = self.send(prep, **send_kwargs)
  File "/Users/max/opt/anaconda3/lib/python3.9/site-packages/requests/sessions.py", line 655, in send
    r = adapter.send(request, **kwargs)
  File "/Users/max/opt/anaconda3/lib/python3.9/site-packages/requests/adapters.py", line 529, in send
    raise ReadTimeout(e, request=request)
requests.exceptions.ReadTimeout: HTTPSConnectionPool(host='api.wandb.ai', port=443): Read timed out. (read timeout=10)
2022-04-26 10:13:37,119 INFO    MainThread:6466 [interface_shared.py:_communicate_run():326] couldn't get run from backend
2022-04-26 10:13:37,119 ERROR   MainThread:6466 [wandb_init.py:init():633] backend process timed out
2022-04-26 10:13:37,119 ERROR   MainThread:6466 [wandb_init.py:init():644] encountered error: Error communicating with wandb process
try: wandb.init(settings=wandb.Settings(start_method='fork'))
or:  wandb.init(settings=wandb.Settings(start_method='thread'))
For more info see: https://docs.wandb.ai/library/init#init-start-error
2022-04-26 10:14:53,137 WARNING MainThread:6466 [wandb_init.py:init():1016] interrupted
Traceback (most recent call last):
  File "/Users/max/opt/anaconda3/lib/python3.9/site-packages/wandb/sdk/wandb_init.py", line 995, in init
    run = wi.init()
  File "/Users/max/opt/anaconda3/lib/python3.9/site-packages/wandb/sdk/wandb_init.py", line 648, in init
    backend.cleanup()
  File "/Users/max/opt/anaconda3/lib/python3.9/site-packages/wandb/sdk/backend/backend.py", line 248, in cleanup
    self.wandb_process.join()
  File "/Users/max/opt/anaconda3/lib/python3.9/multiprocessing/process.py", line 149, in join
    res = self._popen.wait(timeout)
  File "/Users/max/opt/anaconda3/lib/python3.9/multiprocessing/popen_fork.py", line 43, in wait
    return self.poll(os.WNOHANG if timeout == 0.0 else 0)
  File "/Users/max/opt/anaconda3/lib/python3.9/multiprocessing/popen_fork.py", line 27, in poll
    pid, sts = os.waitpid(self.pid, flag)
KeyboardInterrupt
