2022-04-26 10:13:08,424 INFO    MainThread:6474 [internal.py:wandb_internal():90] W&B internal server running at pid: 6474, started at: 2022-04-26 10:13:08.423911
2022-04-26 10:13:08,425 INFO    WriterThread:6474 [datastore.py:open_for_write():75] open: /Users/max/Developer/future-studio-lab/dalle-playground/backend/wandb/run-20220426_101307-234c0qrn/run-234c0qrn.wandb
2022-04-26 10:13:08,428 DEBUG   SenderThread:6474 [sender.py:send():232] send: header
2022-04-26 10:13:08,428 DEBUG   SenderThread:6474 [sender.py:send():232] send: run
2022-04-26 10:13:37,120 DEBUG   HandlerThread:6474 [handler.py:handle_request():141] handle_request: shutdown
2022-04-26 10:13:37,121 INFO    HandlerThread:6474 [handler.py:finish():806] shutting down handler
2022-04-26 10:13:37,523 INFO    WriterThread:6474 [datastore.py:close():279] close: /Users/max/Developer/future-studio-lab/dalle-playground/backend/wandb/run-20220426_101307-234c0qrn/run-234c0qrn.wandb
2022-04-26 10:13:43,834 ERROR   SenderThread:6474 [retry.py:__call__():126] Retry attempt failed:
Traceback (most recent call last):
  File "/Users/max/opt/anaconda3/lib/python3.9/site-packages/urllib3/connectionpool.py", line 445, in _make_request
    six.raise_from(e, None)
  File "<string>", line 3, in raise_from
  File "/Users/max/opt/anaconda3/lib/python3.9/site-packages/urllib3/connectionpool.py", line 440, in _make_request
    httplib_response = conn.getresponse()
  File "/Users/max/opt/anaconda3/lib/python3.9/http/client.py", line 1371, in getresponse
    response.begin()
  File "/Users/max/opt/anaconda3/lib/python3.9/http/client.py", line 319, in begin
    version, status, reason = self._read_status()
  File "/Users/max/opt/anaconda3/lib/python3.9/http/client.py", line 280, in _read_status
    line = str(self.fp.readline(_MAXLINE + 1), "iso-8859-1")
  File "/Users/max/opt/anaconda3/lib/python3.9/socket.py", line 704, in readinto
    return self._sock.recv_into(b)
  File "/Users/max/opt/anaconda3/lib/python3.9/ssl.py", line 1241, in recv_into
    return self.read(nbytes, buffer)
  File "/Users/max/opt/anaconda3/lib/python3.9/ssl.py", line 1099, in read
    return self._sslobj.read(len, buffer)
socket.timeout: The read operation timed out

During handling of the above exception, another exception occurred:

Traceback (most recent call last):
  File "/Users/max/opt/anaconda3/lib/python3.9/site-packages/requests/adapters.py", line 439, in send
    resp = conn.urlopen(
  File "/Users/max/opt/anaconda3/lib/python3.9/site-packages/urllib3/connectionpool.py", line 755, in urlopen
    retries = retries.increment(
  File "/Users/max/opt/anaconda3/lib/python3.9/site-packages/urllib3/util/retry.py", line 532, in increment
    raise six.reraise(type(error), error, _stacktrace)
  File "/Users/max/opt/anaconda3/lib/python3.9/site-packages/urllib3/packages/six.py", line 770, in reraise
    raise value
  File "/Users/max/opt/anaconda3/lib/python3.9/site-packages/urllib3/connectionpool.py", line 699, in urlopen
    httplib_response = self._make_request(
  File "/Users/max/opt/anaconda3/lib/python3.9/site-packages/urllib3/connectionpool.py", line 447, in _make_request
    self._raise_timeout(err=e, url=url, timeout_value=read_timeout)
  File "/Users/max/opt/anaconda3/lib/python3.9/site-packages/urllib3/connectionpool.py", line 336, in _raise_timeout
    raise ReadTimeoutError(
urllib3.exceptions.ReadTimeoutError: HTTPSConnectionPool(host='api.wandb.ai', port=443): Read timed out. (read timeout=10)

During handling of the above exception, another exception occurred:

Traceback (most recent call last):
  File "/Users/max/opt/anaconda3/lib/python3.9/site-packages/wandb/sdk/lib/retry.py", line 102, in __call__
    result = self._call_fn(*args, **kwargs)
  File "/Users/max/opt/anaconda3/lib/python3.9/site-packages/wandb/sdk/internal/internal_api.py", line 140, in execute
    return self.client.execute(*args, **kwargs)
  File "/Users/max/opt/anaconda3/lib/python3.9/site-packages/wandb/vendor/gql-0.2.0/wandb_gql/client.py", line 52, in execute
    result = self._get_result(document, *args, **kwargs)
  File "/Users/max/opt/anaconda3/lib/python3.9/site-packages/wandb/vendor/gql-0.2.0/wandb_gql/client.py", line 60, in _get_result
    return self.transport.execute(document, *args, **kwargs)
  File "/Users/max/opt/anaconda3/lib/python3.9/site-packages/wandb/vendor/gql-0.2.0/wandb_gql/transport/requests.py", line 38, in execute
    request = requests.post(self.url, **post_args)
  File "/Users/max/opt/anaconda3/lib/python3.9/site-packages/requests/api.py", line 117, in post
    return request('post', url, data=data, json=json, **kwargs)
  File "/Users/max/opt/anaconda3/lib/python3.9/site-packages/requests/api.py", line 61, in request
    return session.request(method=method, url=url, **kwargs)
  File "/Users/max/opt/anaconda3/lib/python3.9/site-packages/requests/sessions.py", line 542, in request
    resp = self.send(prep, **send_kwargs)
  File "/Users/max/opt/anaconda3/lib/python3.9/site-packages/requests/sessions.py", line 655, in send
    r = adapter.send(request, **kwargs)
  File "/Users/max/opt/anaconda3/lib/python3.9/site-packages/requests/adapters.py", line 529, in send
    raise ReadTimeout(e, request=request)
requests.exceptions.ReadTimeout: HTTPSConnectionPool(host='api.wandb.ai', port=443): Read timed out. (read timeout=10)
2022-04-26 10:14:53,394 INFO    MainThread:6474 [internal.py:handle_exit():80] Internal process exited
