Traceback (most recent call last):
  File "/Users/max/opt/anaconda3/lib/python3.9/site-packages/transformers/configuration_utils.py", line 645, in _get_config_dict
    config_dict = cls._dict_from_json_file(resolved_config_file)
  File "/Users/max/opt/anaconda3/lib/python3.9/site-packages/transformers/configuration_utils.py", line 715, in _dict_from_json_file
    text = reader.read()
  File "/Users/max/opt/anaconda3/lib/python3.9/codecs.py", line 322, in decode
    (result, consumed) = self._buffer_decode(data, self.errors, final)
UnicodeDecodeError: 'utf-8' codec can't decode bytes in position 4-5: invalid continuation byte
During handling of the above exception, another exception occurred:
Traceback (most recent call last):
  File "/Users/max/Developer/future-studio-lab/dalle-playground/backend/app.py", line 63, in <module>
    model = DalleBart.from_pretrained(DALLE_MODEL, revision=DALLE_COMMIT_ID, dtype=dtype, abstract_init=True)
  File "/Users/max/opt/anaconda3/lib/python3.9/site-packages/dalle_mini/model/utils.py", line 25, in from_pretrained
    return super(PretrainedFromWandbMixin, cls).from_pretrained(
  File "/Users/max/opt/anaconda3/lib/python3.9/site-packages/dalle_mini/model/modeling.py", line 1310, in from_pretrained
    config, model_kwargs = cls.config_class.from_pretrained(
  File "/Users/max/opt/anaconda3/lib/python3.9/site-packages/dalle_mini/model/utils.py", line 25, in from_pretrained
    return super(PretrainedFromWandbMixin, cls).from_pretrained(
  File "/Users/max/opt/anaconda3/lib/python3.9/site-packages/transformers/configuration_utils.py", line 521, in from_pretrained
    config_dict, kwargs = cls.get_config_dict(pretrained_model_name_or_path, **kwargs)
  File "/Users/max/opt/anaconda3/lib/python3.9/site-packages/transformers/configuration_utils.py", line 548, in get_config_dict
    config_dict, kwargs = cls._get_config_dict(pretrained_model_name_or_path, **kwargs)
  File "/Users/max/opt/anaconda3/lib/python3.9/site-packages/transformers/configuration_utils.py", line 647, in _get_config_dict
    raise EnvironmentError(
OSError: It looks like the config file at './wandb/run-20220421_120039-36xut6fr/run-36xut6fr.wandb' is not a valid JSON file.